<?xml version="1.0" encoding="utf-8"?>
<!-- This URDF was automatically created by SolidWorks to URDF Exporter! Originally created by Stephen Brawner (brawner@gmail.com) 
     Commit Version: 1.6.0-4-g7f85cfe  Build Version: 1.6.7995.38578
     For more information, please see http://wiki.ros.org/sw_urdf_exporter -->
<robot
  name="iabot_0811">
  <link
    name="base_link">
    <inertial>
      <origin
        xyz="0.022932 -0.005675 -0.087903"
        rpy="0 0 0" />
      <mass
        value="15.862" />
      <inertia
        ixx="0.27465"
        ixy="-7.1995E-06"
        ixz="0.0050561"
        iyy="0.13652"
        iyz="-1.5511E-05"
        izz="0.29154" />
    </inertial>
    <visual>
      <origin
        xyz="0 0 0"
        rpy="0 0 0" />
      <geometry>
        <mesh
          filename="package://iabot_0811/meshes/base_link.STL" />
      </geometry>
      <material
        name="">
        <color
          rgba="0.75294 0.75294 0.75294 1" />
      </material>
    </visual>
    <collision>
      <origin
        xyz="0 0 0"
        rpy="0 0 0" />
      <geometry>
        <mesh
          filename="package://iabot_0811/meshes/base_link.STL" />
      </geometry>
    </collision>
  </link>
  <link
    name="Leg-front-left-0003">
    <inertial>
      <origin
        xyz="-0.10474 -0.021486 0.031227"
        rpy="0 0 0" />
      <mass
        value="2" />
      <inertia
        ixx="0.00032941"
        ixy="-0.00021609"
        ixz="0.0001005"
        iyy="0.0013385"
        iyz="2.0618E-05"
        izz="0.0014664" />
    </inertial>
    <visual>
      <origin
        xyz="0 0 0"
        rpy="0 0 0" />
      <geometry>
        <mesh
          filename="package://iabot_0811/meshes/Leg-front-left-0003.STL" />
      </geometry>
      <material
        name="">
        <color
          rgba="0.75294 0.75294 0.75294 1" />
      </material>
    </visual>
    <collision>
      <origin
        xyz="0 0 0"
        rpy="0 0 0" />
      <geometry>
        <mesh
          filename="package://iabot_0811/meshes/Leg-front-left-0003.STL" />
      </geometry>
    </collision>
  </link>
  <joint
    name="Leg-front-left-0003"
    type="continuous">
    <origin
      xyz="-0.3 -0.265 -0.4179"
      rpy="0 0 0" />
    <parent
      link="base_link" />
    <child
      link="Leg-front-left-0003" />
    <axis
      xyz="0 0 -1" />
  </joint>
  <link
    name="Leg-front-left-0002">
    <inertial>
      <origin
        xyz="0.039593 -0.00010099 -0.022141"
        rpy="0 0 0" />
      <mass
        value="2" />
      <inertia
        ixx="0.00029781"
        ixy="1.2527E-07"
        ixz="8.9915E-05"
        iyy="0.00034692"
        iyz="-2.2939E-07"
        izz="0.0002269" />
    </inertial>
    <visual>
      <origin
        xyz="0 0 0"
        rpy="0 0 0" />
      <geometry>
        <mesh
          filename="package://iabot_0811/meshes/Leg-front-left-0002.STL" />
      </geometry>
      <material
        name="">
        <color
          rgba="0.89804 0.91765 0.92941 1" />
      </material>
    </visual>
    <collision>
      <origin
        xyz="0 0 0"
        rpy="0 0 0" />
      <geometry>
        <mesh
          filename="package://iabot_0811/meshes/Leg-front-left-0002.STL" />
      </geometry>
    </collision>
  </link>
  <joint
    name="Leg-front-left-0002"
    type="continuous">
    <origin
      xyz="-0.19592 -0.04019 -0.0001"
      rpy="0 0 0" />
    <parent
      link="Leg-front-left-0003" />
    <child
      link="Leg-front-left-0002" />
    <axis
      xyz="0 0 -1" />
  </joint>
  <link
    name="Leg-front-left-0001">
    <inertial>
      <origin
        xyz="0 -0.000507 -0.00045094"
        rpy="0 0 0" />
      <mass
        value="5" />
      <inertia
        ixx="0.0025574"
        ixy="-8.4207E-21"
        ixz="-1.2282E-20"
        iyy="0.0024726"
        iyz="-1.1806E-05"
        izz="0.0037023" />
    </inertial>
    <visual>
      <origin
        xyz="0 0 0"
        rpy="0 0 0" />
      <geometry>
        <mesh
          filename="package://iabot_0811/meshes/Leg-front-left-0001.STL" />
      </geometry>
      <material
        name="">
        <color
          rgba="1 1 1 1" />
      </material>
    </visual>
    <collision>
      <origin
        xyz="0 0 0"
        rpy="0 0 0" />
      <geometry>
        <mesh
          filename="package://iabot_0811/meshes/Leg-front-left-0001.STL" />
      </geometry>
    </collision>
  </link>
  <joint
    name="Leg-front-left-0001"
    type="continuous">
    <origin
      xyz="0 0 -0.102"
      rpy="-1.5708 0 1.5682" />
    <parent
      link="Leg-front-left-0002" />
    <child
      link="Leg-front-left-0001" />
    <axis
      xyz="0 0 -1" />
  </joint>
  <link
    name="Leg-front-right-0003">
    <inertial>
      <origin
        xyz="-0.092087 0.054335 0.031227"
        rpy="0 0 0" />
      <mass
        value="2" />
      <inertia
        ixx="0.00056856"
        ixy="0.00048043"
        ixz="8.8359E-05"
        iyy="0.0010993"
        iyz="-5.2134E-05"
        izz="0.0014664" />
    </inertial>
    <visual>
      <origin
        xyz="0 0 0"
        rpy="0 0 0" />
      <geometry>
        <mesh
          filename="package://iabot_0811/meshes/Leg-front-right-0003.STL" />
      </geometry>
      <material
        name="">
        <color
          rgba="0.75294 0.75294 0.75294 1" />
      </material>
    </visual>
    <collision>
      <origin
        xyz="0 0 0"
        rpy="0 0 0" />
      <geometry>
        <mesh
          filename="package://iabot_0811/meshes/Leg-front-right-0003.STL" />
      </geometry>
    </collision>
  </link>
  <joint
    name="Leg-front-right-0003"
    type="continuous">
    <origin
      xyz="-0.3 0.265 -0.4179"
      rpy="0 0 0" />
    <parent
      link="base_link" />
    <child
      link="Leg-front-right-0003" />
    <axis
      xyz="0 0 -1" />
  </joint>
  <link
    name="Leg-front-right-0002">
    <inertial>
      <origin
        xyz="0.039497 0.002755 -0.022141"
        rpy="0 0 0" />
      <mass
        value="2" />
      <inertia
        ixx="0.00029805"
        ixy="-3.409E-06"
        ixz="8.9697E-05"
        iyy="0.00034668"
        iyz="6.2567E-06"
        izz="0.0002269" />
    </inertial>
    <visual>
      <origin
        xyz="0 0 0"
        rpy="0 0 0" />
      <geometry>
        <mesh
          filename="package://iabot_0811/meshes/Leg-front-right-0002.STL" />
      </geometry>
      <material
        name="">
        <color
          rgba="0.89804 0.91765 0.92941 1" />
      </material>
    </visual>
    <collision>
      <origin
        xyz="0 0 0"
        rpy="0 0 0" />
      <geometry>
        <mesh
          filename="package://iabot_0811/meshes/Leg-front-right-0002.STL" />
      </geometry>
    </collision>
  </link>
  <joint
    name="Leg-front-right-0002"
    type="continuous">
    <origin
      xyz="-0.17225 0.10163 -0.0001"
      rpy="0 0 0" />
    <parent
      link="Leg-front-right-0003" />
    <child
      link="Leg-front-right-0002" />
    <axis
      xyz="0 0 -1" />
  </joint>
  <link
    name="Leg-front-right-0001">
    <inertial>
      <origin
        xyz="0.00021715 0.00045814 -0.00045094"
        rpy="0 0 0" />
      <mass
        value="5" />
      <inertia
        ixx="0.0025419"
        ixy="-3.2827E-05"
        ixz="5.0567E-06"
        iyy="0.0024882"
        iyz="1.0668E-05"
        izz="0.0037023" />
    </inertial>
    <visual>
      <origin
        xyz="0 0 0"
        rpy="0 0 0" />
      <geometry>
        <mesh
          filename="package://iabot_0811/meshes/Leg-front-right-0001.STL" />
      </geometry>
      <material
        name="">
        <color
          rgba="1 1 1 1" />
      </material>
    </visual>
    <collision>
      <origin
        xyz="0 0 0"
        rpy="0 0 0" />
      <geometry>
        <mesh
          filename="package://iabot_0811/meshes/Leg-front-right-0001.STL" />
      </geometry>
    </collision>
  </link>
  <joint
    name="Leg-front-right-0001"
    type="continuous">
    <origin
      xyz="0 0 -0.102"
      rpy="1.5708 0 -1.5012" />
    <parent
      link="Leg-front-right-0002" />
    <child
      link="Leg-front-right-0001" />
    <axis
      xyz="0 0 -1" />
  </joint>
  <link
    name="Leg-back-left-0002">
    <inertial>
      <origin
        xyz="0.03886 -0.0075811 -0.022141"
        rpy="0 0 0" />
      <mass
        value="2" />
      <inertia
        ixx="0.00029961"
        ixy="9.2295E-06"
        ixz="8.8251E-05"
        iyy="0.00034512"
        iyz="-1.7217E-05"
        izz="0.0002269" />
    </inertial>
    <visual>
      <origin
        xyz="0 0 0"
        rpy="0 0 0" />
      <geometry>
        <mesh
          filename="package://iabot_0811/meshes/Leg-back-left-0002.STL" />
      </geometry>
      <material
        name="">
        <color
          rgba="0.89804 0.91765 0.92941 1" />
      </material>
    </visual>
    <collision>
      <origin
        xyz="0 0 0"
        rpy="0 0 0" />
      <geometry>
        <mesh
          filename="package://iabot_0811/meshes/Leg-back-left-0002.STL" />
      </geometry>
    </collision>
  </link>
  <joint
    name="Leg-back-left-0002"
    type="continuous">
    <origin
      xyz="0.5 -0.265 -0.418"
      rpy="0 0 0" />
    <parent
      link="base_link" />
    <child
      link="Leg-back-left-0002" />
    <axis
      xyz="0 0 -1" />
  </joint>
  <link
    name="Leg-back-left-0001">
    <inertial>
      <origin
        xyz="4.2919E-05 0.00050518 -0.00045094"
        rpy="0 0 0" />
      <mass
        value="5" />
      <inertia
        ixx="0.0025568"
        ixy="-7.1543E-06"
        ixz="9.9944E-07"
        iyy="0.0024732"
        iyz="1.1764E-05"
        izz="0.0037023" />
    </inertial>
    <visual>
      <origin
        xyz="0 0 0"
        rpy="0 0 0" />
      <geometry>
        <mesh
          filename="package://iabot_0811/meshes/Leg-back-left-0001.STL" />
      </geometry>
      <material
        name="">
        <color
          rgba="1 1 1 1" />
      </material>
    </visual>
    <collision>
      <origin
        xyz="0 0 0"
        rpy="0 0 0" />
      <geometry>
        <mesh
          filename="package://iabot_0811/meshes/Leg-back-left-0001.STL" />
      </geometry>
    </collision>
  </link>
  <joint
    name="Leg-back-left-0001"
    type="continuous">
    <origin
      xyz="0 0 -0.102"
      rpy="1.5708 0 -1.7635" />
    <parent
      link="Leg-back-left-0002" />
    <child
      link="Leg-back-left-0001" />
    <axis
      xyz="0 0 -1" />
  </joint>
  <link
    name="Leg-back-right-0002">
    <inertial>
      <origin
        xyz="0.013992 0.037038 -0.022141"
        rpy="0 0 0" />
      <mass
        value="2" />
      <inertia
        ixx="0.00034079"
        ixy="-1.6236E-05"
        ixz="3.1777E-05"
        iyy="0.00030394"
        iyz="8.4113E-05"
        izz="0.0002269" />
    </inertial>
    <visual>
      <origin
        xyz="0 0 0"
        rpy="0 0 0" />
      <geometry>
        <mesh
          filename="package://iabot_0811/meshes/Leg-back-right-0002.STL" />
      </geometry>
      <material
        name="">
        <color
          rgba="0.89804 0.91765 0.92941 1" />
      </material>
    </visual>
    <collision>
      <origin
        xyz="0 0 0"
        rpy="0 0 0" />
      <geometry>
        <mesh
          filename="package://iabot_0811/meshes/Leg-back-right-0002.STL" />
      </geometry>
    </collision>
  </link>
  <joint
    name="Leg-back-right-0002"
    type="continuous">
    <origin
      xyz="0.5 0.265 -0.418"
      rpy="0 0 0" />
    <parent
      link="base_link" />
    <child
      link="Leg-back-right-0002" />
    <axis
      xyz="0 0 -1" />
  </joint>
  <link
    name="Leg-back-right-0001">
    <inertial>
      <origin
        xyz="1.4628E-05 0.00050678 -0.00045094"
        rpy="0 0 0" />
      <mass
        value="5" />
      <inertia
        ixx="0.0025573"
        ixy="-2.4462E-06"
        ixz="3.4064E-07"
        iyy="0.0024727"
        iyz="1.1801E-05"
        izz="0.0037023" />
    </inertial>
    <visual>
      <origin
        xyz="0 0 0"
        rpy="0 0 0" />
      <geometry>
        <mesh
          filename="package://iabot_0811/meshes/Leg-back-right-0001.STL" />
      </geometry>
      <material
        name="">
        <color
          rgba="1 1 1 1" />
      </material>
    </visual>
    <collision>
      <origin
        xyz="0 0 0"
        rpy="0 0 0" />
      <geometry>
        <mesh
          filename="package://iabot_0811/meshes/Leg-back-right-0001.STL" />
      </geometry>
    </collision>
  </link>
  <joint
    name="Leg-back-right-0001"
    type="continuous">
    <origin
      xyz="0.0014136 0.0037419 -0.102"
      rpy="1.5708 0 -0.36121" />
    <parent
      link="Leg-back-right-0002" />
    <child
      link="Leg-back-right-0001" />
    <axis
      xyz="0 0 -1" />
  </joint>
  <link
    name="Chest">
    <inertial>
      <origin
        xyz="0.013806 0.285 -0.036079"
        rpy="0 0 0" />
      <mass
        value="30" />
      <inertia
        ixx="0.055468"
        ixy="-0.0016858"
        ixz="-2.666E-07"
        iyy="0.031869"
        iyz="1.886E-08"
        izz="0.040066" />
    </inertial>
    <visual>
      <origin
        xyz="0 0 0"
        rpy="0 0 0" />
      <geometry>
        <mesh
          filename="package://iabot_0811/meshes/Chest.STL" />
      </geometry>
      <material
        name="">
        <color
          rgba="0.75294 0.75294 0.75294 1" />
      </material>
    </visual>
    <collision>
      <origin
        xyz="0 0 0"
        rpy="0 0 0" />
      <geometry>
        <mesh
          filename="package://iabot_0811/meshes/Chest.STL" />
      </geometry>
    </collision>
  </link>
  <joint
    name="chest"
    type="continuous">
    <origin
      xyz="0 0.036 0"
      rpy="1.5708 0 -3.1416" />
    <parent
      link="base_link" />
    <child
      link="Chest" />
    <axis
      xyz="0 0 -1" />
  </joint>
  <link
    name="ARM-LEFT-0001">
    <inertial>
      <origin
        xyz="-0.00076558 0.001048 0.033636"
        rpy="0 0 0" />
      <mass
        value="2" />
      <inertia
        ixx="0.00037018"
        ixy="-1.8159E-05"
        ixz="-2.7968E-06"
        iyy="0.00038248"
        iyz="3.7131E-06"
        izz="0.00037932" />
    </inertial>
    <visual>
      <origin
        xyz="0 0 0"
        rpy="0 0 0" />
      <geometry>
        <mesh
          filename="package://iabot_0811/meshes/ARM-LEFT-0001.STL" />
      </geometry>
      <material
        name="">
        <color
          rgba="0.75294 0.75294 0.75294 1" />
      </material>
    </visual>
    <collision>
      <origin
        xyz="0 0 0"
        rpy="0 0 0" />
      <geometry>
        <mesh
          filename="package://iabot_0811/meshes/ARM-LEFT-0001.STL" />
      </geometry>
    </collision>
  </link>
  <joint
    name="ARM-LEFT-0001"
    type="continuous">
    <origin
      xyz="0.036864 0.51869 -0.2055"
      rpy="-3.1416 0 -3.1416" />
    <parent
      link="Chest" />
    <child
      link="ARM-LEFT-0001" />
    <axis
      xyz="0 0 1" />
  </joint>
  <link
    name="ARM-LEFT-0002">
    <inertial>
      <origin
        xyz="-0.033283 -0.15426 -0.037548"
        rpy="0 0 0" />
      <mass
        value="2" />
      <inertia
        ixx="0.010927"
        ixy="-0.0020367"
        ixz="-4.0125E-05"
        iyy="0.0019296"
        iyz="-0.00018566"
        izz="0.011775" />
    </inertial>
    <visual>
      <origin
        xyz="0 0 0"
        rpy="0 0 0" />
      <geometry>
        <mesh
          filename="package://iabot_0811/meshes/ARM-LEFT-0002.STL" />
      </geometry>
      <material
        name="">
        <color
          rgba="0.75294 0.75294 0.75294 1" />
      </material>
    </visual>
    <collision>
      <origin
        xyz="0 0 0"
        rpy="0 0 0" />
      <geometry>
        <mesh
          filename="package://iabot_0811/meshes/ARM-LEFT-0002.STL" />
      </geometry>
    </collision>
  </link>
  <joint
    name="ARM-LEFT-0002"
    type="continuous">
    <origin
      xyz="0.027374 -0.038205 0.0755"
      rpy="0.94908 1.5708 0" />
    <parent
      link="ARM-LEFT-0001" />
    <child
      link="ARM-LEFT-0002" />
    <axis
      xyz="0 0 -1" />
  </joint>
  <link
    name="ARM-LEFT-0003">
    <inertial>
      <origin
        xyz="-0.0015113 0.0054329 0.062423"
        rpy="0 0 0" />
      <mass
        value="2" />
      <inertia
        ixx="0.00018625"
        ixy="-1.5658E-05"
        ixz="9.9593E-07"
        iyy="0.00022517"
        iyz="5.7781E-07"
        izz="0.00015848" />
    </inertial>
    <visual>
      <origin
        xyz="0 0 0"
        rpy="0 0 0" />
      <geometry>
        <mesh
          filename="package://iabot_0811/meshes/ARM-LEFT-0003.STL" />
      </geometry>
      <material
        name="">
        <color
          rgba="0.75294 0.75294 0.75294 1" />
      </material>
    </visual>
    <collision>
      <origin
        xyz="0 0 0"
        rpy="0 0 0" />
      <geometry>
        <mesh
          filename="package://iabot_0811/meshes/ARM-LEFT-0003.STL" />
      </geometry>
    </collision>
  </link>
  <joint
    name="ARM-LEFT-0003"
    type="continuous">
    <origin
      xyz="-0.063297 -0.29335 -0.03975"
      rpy="-1.5708 -0.14999 2.9291" />
    <parent
      link="ARM-LEFT-0002" />
    <child
      link="ARM-LEFT-0003" />
    <axis
      xyz="0 0 1" />
  </joint>
  <link
    name="ARM-LEFT-0004">
    <inertial>
      <origin
        xyz="-0.018867 -0.14394 -0.039037"
        rpy="0 0 0" />
      <mass
        value="1.3" />
      <inertia
        ixx="0.0029852"
        ixy="-0.00029143"
        ixz="-6.3415E-06"
        iyy="0.00079999"
        iyz="-4.8381E-05"
        izz="0.0032421" />
    </inertial>
    <visual>
      <origin
        xyz="0 0 0"
        rpy="0 0 0" />
      <geometry>
        <mesh
          filename="package://iabot_0811/meshes/ARM-LEFT-0004.STL" />
      </geometry>
      <material
        name="">
        <color
          rgba="0.75294 0.75294 0.75294 1" />
      </material>
    </visual>
    <collision>
      <origin
        xyz="0 0 0"
        rpy="0 0 0" />
      <geometry>
        <mesh
          filename="package://iabot_0811/meshes/ARM-LEFT-0004.STL" />
      </geometry>
    </collision>
  </link>
  <joint
    name="ARM-LEFT-0004"
    type="continuous">
    <origin
      xyz="0.014316 -0.042398 0.079053"
      rpy="-1.5708 0.43318 -2.8156" />
    <parent
      link="ARM-LEFT-0003" />
    <child
      link="ARM-LEFT-0004" />
    <axis
      xyz="0 0 1" />
  </joint>
  <link
    name="ARM-LEFT-0005">
    <inertial>
      <origin
        xyz="0.00094319 0.0013084 0.0099139"
        rpy="0 0 0" />
      <mass
        value="0.5" />
      <inertia
        ixx="1.1212E-05"
        ixy="-1.3126E-06"
        ixz="-3.0852E-07"
        iyy="1.0338E-05"
        iyz="-4.2797E-07"
        izz="1.2718E-05" />
    </inertial>
    <visual>
      <origin
        xyz="0 0 0"
        rpy="0 0 0" />
      <geometry>
        <mesh
          filename="package://iabot_0811/meshes/ARM-LEFT-0005.STL" />
      </geometry>
      <material
        name="">
        <color
          rgba="0.75294 0.75294 0.75294 1" />
      </material>
    </visual>
    <collision>
      <origin
        xyz="0 0 0"
        rpy="0 0 0" />
      <geometry>
        <mesh
          filename="package://iabot_0811/meshes/ARM-LEFT-0005.STL" />
      </geometry>
    </collision>
  </link>
  <joint
    name="ARM-LEFT-0005"
    type="continuous">
    <origin
      xyz="-0.036317 -0.27707 -0.04225"
      rpy="-1.5708 -0.10429 3.0113" />
    <parent
      link="ARM-LEFT-0004" />
    <child
      link="ARM-LEFT-0005" />
    <axis
      xyz="0 0 1" />
  </joint>
  <link
    name="ARM-LEFT-0006">
    <inertial>
      <origin
        xyz="-0.05069 -0.02351 -0.0098048"
        rpy="0 0 0" />
      <mass
        value="0.2" />
      <inertia
        ixx="8.5224E-06"
        ixy="-8.2216E-06"
        ixz="-4.9023E-06"
        iyy="2.2436E-05"
        iyz="-2.2737E-06"
        izz="2.2874E-05" />
    </inertial>
    <visual>
      <origin
        xyz="0 0 0"
        rpy="0 0 0" />
      <geometry>
        <mesh
          filename="package://iabot_0811/meshes/ARM-LEFT-0006.STL" />
      </geometry>
      <material
        name="">
        <color
          rgba="0.86667 0.86667 0.8902 1" />
      </material>
    </visual>
    <collision>
      <origin
        xyz="0 0 0"
        rpy="0 0 0" />
      <geometry>
        <mesh
          filename="package://iabot_0811/meshes/ARM-LEFT-0006.STL" />
      </geometry>
    </collision>
  </link>
  <joint
    name="ARM-LEFT-0006"
    type="continuous">
    <origin
      xyz="0.017543 0.024336 0.0335"
      rpy="-1.5708 0.63466 -0.62461" />
    <parent
      link="ARM-LEFT-0005" />
    <child
      link="ARM-LEFT-0006" />
    <axis
      xyz="0 0 -1" />
  </joint>
  <link
    name="ARM-RIGHT-0001">
    <inertial>
      <origin
        xyz="-0.00050887 -0.0011939 0.033636"
        rpy="0 0 0" />
      <mass
        value="2" />
      <inertia
        ixx="0.0003633"
        ixy="1.4064E-05"
        ixz="-1.7599E-06"
        iyy="0.00038936"
        iyz="-4.3025E-06"
        izz="0.00037932" />
    </inertial>
    <visual>
      <origin
        xyz="0 0 0"
        rpy="0 0 0" />
      <geometry>
        <mesh
          filename="package://iabot_0811/meshes/ARM-RIGHT-0001.STL" />
      </geometry>
      <material
        name="">
        <color
          rgba="0.75294 0.75294 0.75294 1" />
      </material>
    </visual>
    <collision>
      <origin
        xyz="0 0 0"
        rpy="0 0 0" />
      <geometry>
        <mesh
          filename="package://iabot_0811/meshes/ARM-RIGHT-0001.STL" />
      </geometry>
    </collision>
  </link>
  <joint
    name="ARM-RIGHT-0001"
    type="continuous">
    <origin
      xyz="0.036864 0.51869 0.1335"
      rpy="0 0 0" />
    <parent
      link="Chest" />
    <child
      link="ARM-RIGHT-0001" />
    <axis
      xyz="0 0 1" />
  </joint>
  <link
    name="ARM-RIGHT-0002">
    <inertial>
      <origin
        xyz="-0.077801 -0.1373 -0.037549"
        rpy="0 0 0" />
      <mass
        value="2" />
      <inertia
        ixx="0.0089655"
        ixy="-0.0042365"
        ixz="-9.3701E-05"
        iyy="0.0038909"
        iyz="-0.00016523"
        izz="0.011775" />
    </inertial>
    <visual>
      <origin
        xyz="0 0 0"
        rpy="0 0 0" />
      <geometry>
        <mesh
          filename="package://iabot_0811/meshes/ARM-RIGHT-0002.STL" />
      </geometry>
      <material
        name="">
        <color
          rgba="0.75294 0.75294 0.75294 1" />
      </material>
    </visual>
    <collision>
      <origin
        xyz="0 0 0"
        rpy="0 0 0" />
      <geometry>
        <mesh
          filename="package://iabot_0811/meshes/ARM-RIGHT-0002.STL" />
      </geometry>
    </collision>
  </link>
  <joint
    name="ARM-RIGHT-0002"
    type="continuous">
    <origin
      xyz="0.018826 0.043065 0.0755"
      rpy="1.1587 1.5708 0" />
    <parent
      link="ARM-RIGHT-0001" />
    <child
      link="ARM-RIGHT-0002" />
    <axis
      xyz="0 0 -1" />
  </joint>
  <link
    name="ARM-RIGHT-0003">
    <inertial>
      <origin
        xyz="0.0012721 0.0054938 0.062422"
        rpy="0 0 0" />
      <mass
        value="2" />
      <inertia
        ixx="0.000182"
        ixy="7.8608E-06"
        ixz="1.151E-06"
        iyy="0.00022941"
        iyz="3.0942E-08"
        izz="0.00015848" />
    </inertial>
    <visual>
      <origin
        xyz="0 0 0"
        rpy="0 0 0" />
      <geometry>
        <mesh
          filename="package://iabot_0811/meshes/ARM-RIGHT-0003.STL" />
      </geometry>
      <material
        name="">
        <color
          rgba="0.75294 0.75294 0.75294 1" />
      </material>
    </visual>
    <collision>
      <origin
        xyz="0 0 0"
        rpy="0 0 0" />
      <geometry>
        <mesh
          filename="package://iabot_0811/meshes/ARM-RIGHT-0003.STL" />
      </geometry>
    </collision>
  </link>
  <joint
    name="ARM-RIGHT-0003"
    type="continuous">
    <origin
      xyz="-0.14795 -0.26109 -0.03975"
      rpy="1.5708 -0.21227 -0.51554" />
    <parent
      link="ARM-RIGHT-0002" />
    <child
      link="ARM-RIGHT-0003" />
    <axis
      xyz="0 0 1" />
  </joint>
  <link
    name="ARM-RIGHT-0004">
    <inertial>
      <origin
        xyz="-0.032471 -0.1415 0.039037"
        rpy="0 0 0" />
      <mass
        value="1.3" />
      <inertia
        ixx="0.0029102"
        ixy="-0.00049302"
        ixz="1.0914E-05"
        iyy="0.00087492"
        iyz="4.7559E-05"
        izz="0.0032421" />
    </inertial>
    <visual>
      <origin
        xyz="0 0 0"
        rpy="0 0 0" />
      <geometry>
        <mesh
          filename="package://iabot_0811/meshes/ARM-RIGHT-0004.STL" />
      </geometry>
      <material
        name="">
        <color
          rgba="0.75294 0.75294 0.75294 1" />
      </material>
    </visual>
    <collision>
      <origin
        xyz="0 0 0"
        rpy="0 0 0" />
      <geometry>
        <mesh
          filename="package://iabot_0811/meshes/ARM-RIGHT-0004.STL" />
      </geometry>
    </collision>
  </link>
  <joint
    name="ARM-RIGHT-0004"
    type="continuous">
    <origin
      xyz="-0.007684 -0.044085 0.079055"
      rpy="-1.5708 0.43322 -0.17282" />
    <parent
      link="ARM-RIGHT-0003" />
    <child
      link="ARM-RIGHT-0004" />
    <axis
      xyz="0 0 -1" />
  </joint>
  <link
    name="ARM-RIGHT-0005">
    <inertial>
      <origin
        xyz="-5.9771E-07 -0.0016129 0.0099139"
        rpy="0 0 0" />
      <mass
        value="0.5" />
      <inertia
        ixx="1.2159E-05"
        ixy="-1.0038E-09"
        ixz="1.9162E-10"
        iyy="9.3915E-06"
        iyz="5.2758E-07"
        izz="1.2718E-05" />
    </inertial>
    <visual>
      <origin
        xyz="0 0 0"
        rpy="0 0 0" />
      <geometry>
        <mesh
          filename="package://iabot_0811/meshes/ARM-RIGHT-0005.STL" />
      </geometry>
      <material
        name="">
        <color
          rgba="0.75294 0.75294 0.75294 1" />
      </material>
    </visual>
    <collision>
      <origin
        xyz="0 0 0"
        rpy="0 0 0" />
      <geometry>
        <mesh
          filename="package://iabot_0811/meshes/ARM-RIGHT-0005.STL" />
      </geometry>
    </collision>
  </link>
  <joint
    name="ARM-RIGHT-0005"
    type="continuous">
    <origin
      xyz="-0.062502 -0.27236 0.04225"
      rpy="1.5708 -0.092739 -0.22557" />
    <parent
      link="ARM-RIGHT-0004" />
    <child
      link="ARM-RIGHT-0005" />
    <axis
      xyz="0 0 1" />
  </joint>
  <link
    name="ARM-RIGHT-0006">
    <inertial>
      <origin
        xyz="0.054965 0.010053 -0.0098048"
        rpy="0 0 0" />
      <mass
        value="0.2" />
      <inertia
        ixx="5.4065E-06"
        ixy="-3.8122E-06"
        ixz="5.3157E-06"
        iyy="2.5552E-05"
        iyz="9.7228E-07"
        izz="2.2874E-05" />
    </inertial>
    <visual>
      <origin
        xyz="0 0 0"
        rpy="0 0 0" />
      <geometry>
        <mesh
          filename="package://iabot_0811/meshes/ARM-RIGHT-0006.STL" />
      </geometry>
      <material
        name="">
        <color
          rgba="0.86667 0.86667 0.8902 1" />
      </material>
    </visual>
    <collision>
      <origin
        xyz="0 0 0"
        rpy="0 0 0" />
      <geometry>
        <mesh
          filename="package://iabot_0811/meshes/ARM-RIGHT-0006.STL" />
      </geometry>
    </collision>
  </link>
  <joint
    name="ARM-RIGHT-0006"
    type="continuous">
    <origin
      xyz="-1.093E-05 -0.03 0.0335"
      rpy="-1.5708 -0.0009028 3.1412" />
    <parent
      link="ARM-RIGHT-0005" />
    <child
      link="ARM-RIGHT-0006" />
    <axis
      xyz="0 0 -1" />
  </joint>
</robot>
